<?xml version="1.0"?>
<robot name="cylindrical_manipulator">
    <!-- Materials -->
    <material name="aluminum">
        <color rgba="0.75 0.75 0.75 1"/>
    </material>
    
    <!-- World Fixed Base -->
    <link name="world"/>
    
    <!-- Base Link -->
    <joint name="fixed" type="fixed">
        <parent link="world"/>
        <child link="base_link"/>
        <origin xyz="0 0 0" rpy="0 0 0"/>
    </joint>
    
    <link name="base_link">
        <visual>
            <origin xyz="0 0 0.25" rpy="0 0 0"/>
            <geometry>
                <cylinder radius="0.2" length="0.5"/>
            </geometry>
            <material name="aluminum"/>
        </visual>
        <collision>
            <origin xyz="0 0 0.25" rpy="0 0 0"/>
            <geometry>
                <cylinder radius="0.2" length="0.5"/>
            </geometry>
        </collision>
        <inertial>
            <origin xyz="0 0 0.25" rpy="0 0 0"/>
            <mass value="15"/>
            <inertia ixx="0.5" ixy="0" ixz="0" iyy="0.5" iyz="0" izz="0.3"/>
        </inertial>
    </link>

    <!-- Base Rotation Joint (1st DOF) -->
    <joint name="base_rotation" type="revolute">
        <parent link="base_link"/>
        <child link="vertical_link"/>
        <origin xyz="0 0 0.5" rpy="0 0 0"/>
        <axis xyz="0 0 1"/>
        <limit lower="-1.5708" upper="1.5708" effort="400" velocity="1.0"/>
    </joint>

    <!-- Vertical Link -->
    <link name="vertical_link">
        <visual>
            <origin xyz="0 0 1.0" rpy="0 0 0"/>
            <geometry>
                <cylinder radius="0.1" length="2.0"/>
            </geometry>
            <material name="aluminum"/>
        </visual>
        <collision>
            <origin xyz="0 0 1.0" rpy="0 0 0"/>
            <geometry>
                <cylinder radius="0.1" length="2.0"/>
            </geometry>
        </collision>
        <inertial>
            <origin xyz="0 0 1.0" rpy="0 0 0"/>
            <mass value="12"/>
            <inertia ixx="4.0" ixy="0" ixz="0" iyy="4.0" iyz="0" izz="0.06"/>
        </inertial>
    </link>

    <!-- Vertical Prismatic Joint (2nd DOF) -->
    <joint name="vertical_prismatic" type="prismatic">
        <parent link="vertical_link"/>
        <child link="horizontal_link"/>
        <origin xyz="0 0 2.0" rpy="0 0 0"/>
        <axis xyz="0 0 1"/>
        <limit lower="-2.0" upper="0" effort="500" velocity="0.5"/>
    </joint>

    <!-- Horizontal Link -->
    <link name="horizontal_link">
        <visual>
            <origin xyz="0.5 0 0" rpy="0 1.5708 0"/>
            <geometry>
                <cylinder radius="0.08" length="1.0"/>
            </geometry>
            <material name="aluminum"/>
        </visual>
        <collision>
            <origin xyz="0.5 0 0" rpy="0 1.5708 0"/>
            <geometry>
                <cylinder radius="0.08" length="1.0"/>
            </geometry>
        </collision>
        <inertial>
            <origin xyz="0.5 0 0" rpy="0 1.5708 0"/>
            <mass value="8"/>
            <inertia ixx="0.067" ixy="0" ixz="0" iyy="0.667" iyz="0" izz="0.667"/>
        </inertial>
    </link>

    <!-- Horizontal Prismatic Joint (3rd DOF) -->
    <joint name="horizontal_prismatic" type="prismatic">
        <parent link="horizontal_link"/>
        <child link="gripper_link"/>
        <origin xyz="1.0 0 0" rpy="0 0 0"/>
        <axis xyz="1 0 0"/>
        <limit lower="0" upper="0.8" effort="300" velocity="0.5"/>
    </joint>

    <!-- Gripper Link -->
    <link name="gripper_link">
        <visual>
            <origin xyz="0 0 0" rpy="0 0 0"/>
            <geometry>
                <box size="0.4 0.4 0.2"/>
            </geometry>
            <material name="aluminum"/>
        </visual>
        <collision>
            <origin xyz="0 0 0" rpy="0 0 0"/>
            <geometry>
                <box size="0.4 0.4 0.2"/>
            </geometry>
        </collision>
        <inertial>
            <origin xyz="0 0 0" rpy="0 0 0"/>
            <mass value="5"/>
            <inertia ixx="0.1" ixy="0" ixz="0" iyy="0.1" iyz="0" izz="0.1"/>
        </inertial>
    </link>
</robot>